Workbook

Sheet Results - Cost Weight
B1: Tier Number | C1: Tier Name | D1: Population (2016) | E1: Population (2021) | F1: 5 Year Met By | G1: 10 Year Met By | H1: 20 Year Met By | J1: Rural Remainder (#) for 10 yr | K1: Rural Remainder (%) for 10 yr | L1: Rural Remainder (#) for 20 yr | M1: Rural Remainder (%) for 20 yr | O1: Specail Weight 10 Yr | P1: Specail Weight 20 yr
B3: 4-001 | C3: St. John's | D3: 255012 | E3: ='DR Threshold Analysis'!D3 -> 257547.97 | F3: ='DR Threshold Analysis'!AI3 -> Metro/Urban | G3: ='DR Threshold Analysis'!AK3 -> Metro/Urban | H3: ='DR Threshold Analysis'!AM3 -> Metro/Urban
B4: 4-002 | C4: Placentia | D4: 15304 | E4: ='DR Threshold Analysis'!D4 -> 14303.34 | F4: ='DR Threshold Analysis'!AI4 -> Rural | G4: ='DR Threshold Analysis'!AK4 -> Rural | H4: ='DR Threshold Analysis'!AM4 -> Rural
B5: 4-003 | C5: Gander/Grand Falls/Windsor | D5: 144229 | E5: ='DR Threshold Analysis'!D5 -> 137707.5 | F5: ='DR Threshold Analysis'!AI5 -> Rural | G5: ='DR Threshold Analysis'!AK5 -> Rural | H5: ='DR Threshold Analysis'!AM5 -> Rural
B6: 4-004 | C6: Corner Brook/Stephenville | D6: 77974 | E6: ='DR Threshold Analysis'!D6 -> 74334.09 | F6: ='DR Threshold Analysis'!AI6 -> Rural | G6: ='DR Threshold Analysis'!AK6 -> Rural | H6: ='DR Threshold Analysis'!AM6 -> Rural
B7: 4-005 | C7: Labrador | D7: 27656 | E7: ='DR Threshold Analysis'!D7 -> 26864.59 | F7: ='DR Threshold Analysis'!AI7 -> Remote | G7: ='DR Threshold Analysis'!AK7 -> Remote | H7: ='DR Threshold Analysis'!AM7 -> Remote
B8: 4-006 | C8: Charlottetown | D8: 95350 | E8: ='DR Threshold Analysis'!D8 -> 104131.96 | F8: ='DR Threshold Analysis'!AI8 -> Metro/Urban | G8: ='DR Threshold Analysis'!AK8 -> Metro/Urban | H8: ='DR Threshold Analysis'!AM8 -> Metro/Urban
B9: 4-007 | C9: Summerside | D9: 47557 | E9: ='DR Threshold Analysis'!D9 -> 50199.03 | F9: ='DR Threshold Analysis'!AI9 -> Rural | G9: ='DR Threshold Analysis'!AK9 -> Rural | H9: ='DR Threshold Analysis'!AM9 -> Rural
B10: 4-008 | C10: Yarmouth | D10: 55609 | E10: ='DR Threshold Analysis'!D10 -> 55558.51 | F10: ='DR Threshold Analysis'!AI10 -> Rural | G10: ='DR Threshold Analysis'!AK10 -> Rural | H10: ='DR Threshold Analysis'!AM10 -> Rural
B11: 4-009 | C11: Bridgewater/Kentville | D11: 139289 | E11: ='DR Threshold Analysis'!D11 -> 143860.3 | F11: ='DR Threshold Analysis'!AI11 -> Rural | G11: ='DR Threshold Analysis'!AK11 -> Rural | H11: ='DR Threshold Analysis'!AM11 -> Rural
B12: 4-010 | C12: Halifax | D12: 435820 | E12: ='DR Threshold Analysis'!D12 -> 474931.84 | F12: ='DR Threshold Analysis'!AI12 -> Metro/Urban | G12: ='DR Threshold Analysis'!AK12 -> Metro/Urban | H12: ='DR Threshold Analysis'!AM12 -> Metro/Urban
B13: 4-011 | C13: Truro | D13: 56649 | E13: ='DR Threshold Analysis'!D13 -> 57465.43 | F13: ='DR Threshold Analysis'!AI13 -> Rural | G13: ='DR Threshold Analysis'!AK13 -> Rural | H13: ='DR Threshold Analysis'!AM13 -> Rural
B14: 4-012 | C14: Amherst | D14: 33373 | E14: ='DR Threshold Analysis'!D14 -> 34197.59 | F14: ='DR Threshold Analysis'!AI14 -> Rural | G14: ='DR Threshold Analysis'!AK14 -> Rural | H14: ='DR Threshold Analysis'!AM14 -> Rural
... B18: 4-016 | C18: St. Stephen | D18: 25087 | E18: ='DR Threshold Analysis'!D18 -> 25641.85 | F18: ='DR Threshold Analysis'!AI18 -> Rural | G18: ='DR Threshold Analysis'!AK18 -> Rural | H18: ='DR Threshold Analysis'!AM18 -> Rural
B19: 4-017 | C19: Fredericton | D19: 164871 | E19: ='DR Threshold Analysis'!D19 -> 171650.38 | F19: ='DR Threshold Analysis'!AI19 -> Metro/Urban | G19: ='DR Threshold Analysis'!AK19 -> Metro/Urban | H19: ='DR Threshold Analysis'!AM19 -> Mix | L19: 8328.868 | M19: 10.818254 | P19: 100% Urban + 10% Rural
B20: 4-018 | C20: Moncton | D20: 178500 | E20: ='DR Threshold Analysis'!D20 -> 194002.2 | F20: ='DR Threshold Analysis'!AI20 -> Metro/Urban | G20: ='DR Threshold Analysis'!AK20 -> Metro/Urban | H20: ='DR Threshold Analysis'!AM20 -> Metro/Urban
B21: 4-019 | C21: Miramichi/Bathurst | D21: 156025 | E21: ='DR Threshold Analysis'!D21 -> 157384.33 | F21: ='DR Threshold Analysis'!AI21 -> Rural | G21: ='DR Threshold Analysis'!AK21 -> Rural | H21: ='DR Threshold Analysis'!AM21 -> Rural
B22: 4-020 | C22: Grand Falls | D22: 24936 | E22: ='DR Threshold Analysis'!D22 -> 24315.39 | F22: ='DR Threshold Analysis'!AI22 -> Rural | G22: ='DR Threshold Analysis'!AK22 -> Rural | H22: ='DR Threshold Analysis'!AM22 -> Rural
B23: 4-021 | C23: Edmundston | D23: 26504 | E23: ='DR Threshold Analysis'!D23 -> 26685.66 | F23: ='DR Threshold Analysis'!AI23 -> Rural | G23: ='DR Threshold Analysis'!AK23 -> Rural | H23: ='DR Threshold Analysis'!AM23 -> Rural
B24: 4-022 | C24: Campbellton | D24: 26776 | E24: ='DR Threshold Analysis'!D24 -> 26052.67 | F24: ='DR Threshold Analysis'!AI24 -> Rural | G24: ='DR Threshold Analysis'!AK24 -> Rural | H24: ='DR Threshold Analysis'!AM24 -> Rural
B25: 4-023 | C25: Matane | D25: 112039 | E25: ='DR Threshold Analysis'!D25 -> 111242.45 | F25: ='DR Threshold Analysis'!AI25 -> Rural | G25: ='DR Threshold Analysis'!AK25 -> Rural | H25: ='DR Threshold Analysis'!AM25 -> Rural
B26: 4-024 | C26: Mont-Joli | D26: 37788 | E26: ='DR Threshold Analysis'!D26 -> 37612.68 | F26: ='DR Threshold Analysis'!AI26 -> Rural | G26: ='DR Threshold Analysis'!AK26 -> Rural | H26: ='DR Threshold Analysis'!AM26 -> Rural
B27: 4-025 | C27: Rimouski | D27: 56619 | E27: ='DR Threshold Analysis'!D27 -> 57190.86 | F27: ='DR Threshold Analysis'!AI27 -> Metro/Urban | G27: ='DR Threshold Analysis'!AK27 -> Metro/Urban | H27: ='DR Threshold Analysis'!AM27 -> Metro/Urban
B28: 4-026 | C28: Rivière-du-Loup | D28: 82869 | E28: ='DR Threshold Analysis'!D28 -> 84581.63 | F28: ='DR Threshold Analysis'!AI28 -> Rural | G28: ='DR Threshold Analysis'!AK28 -> Rural | H28: ='DR Threshold Analysis'!AM28 -> Rural
B29: 4-027 | C29: La Malbaie | D29: 28193 | E29: ='DR Threshold Analysis'!D29 -> 28507.84 | F29: ='DR Threshold Analysis'!AI29 -> Rural | G29: ='DR Threshold Analysis'!AK29 -> Rural | H29: ='DR Threshold Analysis'!AM29 -> Rural
B30: 4-028 | C30: Chicoutimi-Jonquière | D30: 218377 | E30: ='DR Threshold Analysis'!D30 -> 218307.6 | F30: ='DR Threshold Analysis'!AI30 -> Metro/Urban | G30: ='DR Threshold Analysis'!AK30 -> Metro/Urban | H30: ='DR Threshold Analysis'!AM30 -> Mix | L30: 26066.95 | M30: 28.470041 | P30: 100% Urban + 28% Rural
B31: 4-029 | C31: Montmagny | D31: 56808 | E31: ='DR Threshold Analysis'!D31 -> 56207.2 | F31: ='DR Threshold Analysis'!AI31 -> Rural | G31: ='DR Threshold Analysis'!AK31 -> Rural | H31: ='DR Threshold Analysis'!AM31 -> Rural
B32: 4-030 | C32: Québec | D32: 904330 | E32: ='DR Threshold Analysis'!D32 -> 942192.61 | F32: ='DR Threshold Analysis'!AI32 -> Metro/Urban | G32: ='DR Threshold Analysis'!AK32 -> Metro/Urban | H32: ='DR Threshold Analysis'!AM32 -> Metro/Urban
B33: 4-031 | C33: Sainte-Marie | D33: 53258 | E33: ='DR Threshold Analysis'!D33 -> 54962.76 | F33: ='DR Threshold Analysis'!AI33 -> Rural | G33: ='DR Threshold Analysis'!AK33 -> Rural | H33: ='DR Threshold Analysis'!AM33 -> Rural
B34: 4-032 | C34: Saint-Georges | D34: 71425 | E34: ='DR Threshold Analysis'!D34 -> 72535.13 | F34: ='DR Threshold Analysis'!AI34 -> Rural | G34: ='DR Threshold Analysis'!AK34 -> Rural | H34: ='DR Threshold Analysis'!AM34 -> Rural
B35: 4-033 | C35: Lac-Mégantic | D35: 24223 | E35: ='DR Threshold Analysis'!D35 -> 24584.22 | F35: ='DR Threshold Analysis'!AI35 -> Rural | G35: ='DR Threshold Analysis'!AK35 -> Rural | H35: ='DR Threshold Analysis'!AM35 -> Rural
B36: 4-034 | C36: Thetford Mines | D36: 42019 | E36: ='DR Threshold Analysis'!D36 -> 43000.79 | F36: ='DR Threshold Analysis'!AI36 -> Rural | G36: ='DR Threshold Analysis'!AK36 -> Rural | H36: ='DR Threshold Analysis'!AM36 -> Rural
B37: 4-035 | C37: Plessisville | D37: 22772 | E37: ='DR Threshold Analysis'!D37 -> 23054.36 | F37: ='DR Threshold Analysis'!AI37 -> Metro/Urban | G37: ='DR Threshold Analysis'!AK37 -> Metro/Urban | H37: ='DR Threshold Analysis'!AM37 -> Metro/Urban
B38: 4-036 | C38: La Tuque | D38: 16219 | E38: ='DR Threshold Analysis'!D38 -> 16376.01 | F38: ='DR Threshold Analysis'!AI38 -> Rural | G38: ='DR Threshold Analysis'!AK38 -> Rural | H38: ='DR Threshold Analysis'!AM38 -> Rural
B39: 4-037 | C39: Trois-Rivières | D39: 265152 | E39: ='DR Threshold Analysis'!D39 -> 272644.1 | F39: ='DR Threshold Analysis'!AI39 -> Metro/Urban | G39: ='DR Threshold Analysis'!AK39 -> Metro/Urban | H39: ='DR Threshold Analysis'!AM39 -> Metro/Urban
B40: 4-038 | C40: Louiseville | D40: 21708 | E40: ='DR Threshold Analysis'!D40 -> 22170.19 | F40: ='DR Threshold Analysis'!AI40 -> Rural | G40: ='DR Threshold Analysis'!AK40 -> Rural | H40: ='DR Threshold Analysis'!AM40 -> Rural
B41: 4-039 | C41: Asbestos | D41: 29744 | E41: ='DR Threshold Analysis'!D41 -> 30262.42 | F41: ='DR Threshold Analysis'!AI41 -> Rural | G41: ='DR Threshold Analysis'!AK41 -> Rural | H41: ='DR Threshold Analysis'!AM41 -> Rural
B42: 4-040 | C42: Victoriaville | D42: 56684 | E42: ='DR Threshold Analysis'!D42 -> 58676.4 | F42: ='DR Threshold Analysis'!AI42 -> Metro/Urban | G42: ='DR Threshold Analysis'!AK42 -> Metro/Urban | H42: ='DR Threshold Analysis'!AM42 -> Metro/Urban
B43: 4-041 | C43: Coaticook | D43: 12981 | E43: ='DR Threshold Analysis'!D43 -> 13002.8 | F43: ='DR Threshold Analysis'!AI43 -> Rural | G43: ='DR Threshold Analysis'!AK43 -> Rural | H43: ='DR Threshold Analysis'!AM43 -> Rural
B44: 4-042 | C44: Sherbrooke | D44: 250227 | E44: ='DR Threshold Analysis'!D44 -> 268189.02 | F44: ='DR Threshold Analysis'!AI44 -> Metro/Urban | G44: ='DR Threshold Analysis'!AK44 -> Metro/Urban | H44: ='DR Threshold Analysis'!AM44 -> Mix | L44: 3895.324 | M44: 4.6179375 | P44: 100% Urban + 5% Rural
...

Sheet 3800 DRs
B1: Tier Number | C1: Tier Name | D1: Population | E1: 5 year or 7 year Requirement | F1: 5 year DR | G1: 10 year DR | H1: 20 year DR
B2: 4-001 | C2: St. John's | D2: 255 012 | E2: 5 | F2: 0.3 | G2: 0.5 | H2: 0.7
B3: 4-010 | C3: Halifax | D3: 435 820 | E3: 5 | F3: 0.3 | G3: 0.5 | H3: 0.7
B4: 4-018 | C4: Moncton | D4: 178 500 | E4: 5 | F4: 0.25 | G4: 0.4 | H4: 0.6
B5: 4-028 | C5: Chicoutimi-Jonquière | D5: 218 377 | E5: 5 | F5: 0.3 | G5: 0.5 | H5: 0.7
B6: 4-030 | C6: Québec | D6: 904 330 | E6: 5 | F6: 0.3 | G6: 0.5 | H6: 0.7
B7: 4-037 | C7: Trois-Rivières | D7: 265 152 | E7: 5 | F7: 0.3 | G7: 0.5 | H7: 0.7
B8: 4-042 | C8: Sherbrooke | D8: 250 227 | E8: 5 | F8: 0.3 | G8: 0.5 | H8: 0.7
B9: 4-051 | C9: Montréal | D9: 4 352 037 | E9: 5 | F9: 0.3 | G9: 0.5 | H9: 0.7
B10: 4-055 | C10: Ottawa | D10: 1 452 852 | E10: 5 | F10: 0.3 | G10: 0.5 | H10: 0.7
B11: 4-070 | C11: Kingston | D11: 177 314 | E11: 5 | F11: 0.3 | G11: 0.5 | H11: 0.7
B12: 4-077 | C12: Toronto | D12: 7 030 750 | E12: 5 | F12: 0.3 | G12: 0.5 | H12: 0.7
B13: 4-079 | C13: Guelph/Kitchener | D13: 707 534 | E13: 5 | F13: 0.3 | G13: 0.5 | H13: 0.7
... B173: 4-172 | C173: Northwest Territories | D173: 41 668 | E173: 7 | F173: 0.2 | G173: 0.35 | H173: 0.5

Sheet DR Threshold Analysis
A1: Tier Number | B1: Tier Name | C1: Population (2016) | D1: Population (2021) | E1: 5 year or 7 year DR | F1: 5 year DR | G1: 10 year DR | H1: 20 year DR | J1: Tier 5 Population Dynamics | O1: Census Difference (Total) | P1: Census Difference (& of 2016 Pop) | R1: Population (2021) | S1: 5 year DR (#) | T1: 10 year DR (#) | U1: 20 year DR (#) | W1: DR met by Metro/Urban | X1: DR met by Rural | Y1: DR met by Remote | AA1: DR met by Metro/Urban | AB1: DR met by Rural | AC1: DR met by Remote | AE1: DR met by Metro/Urban | AF1: DR met by Rural | AG1: DR met by Remote | AI1: 5 yr Met By | AK1: 10 yr Met By | AM1: 20 yr Met By | AO1: Status Change (needs special weight | AP1: Rural Remainder (#) for 10 yr | AQ1: Rural Remainder (%) for 10 yr | AR1: Rural Remainder (#) for 20 yr | AS1: Rural Remainder (%) for 20 yr
J2: Metro | K2: Urban | L2: Rural | M2: Remote
A3: 4-001 | B3: St. John's | C3: 255012 | D3: =SUM(J3:M3) -> 257547.97 | E3: 5 | F3: 0.3 | G3: 0.5 | H3: 0.7 | K3: 212650.9 | L3: 44897.07 | O3: =J3+K3+L3+M3-C3 -> 2535.97 | P3: =((M3+L3+K3+J3)-C3)/C3 -> 0.0099445124 | R3: =SUM(J3:M3) -> 257547.97 | S3: =$D3*(F3) -> 77264.391 | T3: =$D3*(G3) -> 128773.99 | U3: =$D3*(H3) -> 180283.58 | W3: =IF((J3+K3)>S3,"Yes","No") -> Yes | AA3: =IF((J3+K3)>T3,"Yes","No") -> Yes | AE3: =IF((J3+K3)>U3,"Yes","No") -> Yes | AI3: Metro/Urban | AK3: Metro/Urban | AM3: Metro/Urban
A4: 4-002 | B4: Placentia | C4: 15304 | D4: =SUM(J4:M4) -> 14303.34 | E4: 7 | F4: 0.1 | G4: 0.2 | H4: 0.3 | L4: 14303.34 | O4: =J4+K4+L4+M4-C4 -> -1000.66 | P4: =((M4+L4+K4+J4)-C4)/C4 -> -0.06538552 | R4: =SUM(J4:M4) -> 14303.34 | S4: =$D4*(F4) -> 1430.334 | T4: =$D4*(G4) -> 2860.668 | U4: =$D4*(H4) -> 4291.002 | W4: =IF((J4+K4)>S4,"Yes","No") -> No | X4: =IF((L4)>S4,"Yes","No") -> Yes | AA4: =IF((J4+K4)>T4,"Yes","No") -> No | AB4: =IF((L4)>T4,"Yes","No") -> Yes | AE4: =IF((J4+K4)>U4,"Yes","No") -> No | AF4: =IF((L4)>U4,"Yes","No") -> Yes | AI4: Rural | AK4: Rural | AM4: Rural
A5: 4-003 | B5: Gander/Grand Falls/Windsor | C5: 144229 | D5: =SUM(J5:M5) -> 137707.5 | E5: 7 | F5: 0.05 | G5: 0.1 | H5: 0.2 | L5: 137707.5 | O5: =J5+K5+L5+M5-C5 -> -6521.5 | P5: =((M5+L5+K5+J5)-C5)/C5 -> -0.045216288 | R5: =SUM(J5:M5) -> 137707.5 | S5: =$D5*(F5) -> 6885.375 | T5: =$D5*(G5) -> 13770.75 | U5: =$D5*(H5) -> 27541.5 | W5: =IF((J5+K5)>S5,"Yes","No") -> No | X5: =IF((L5)>S5,"Yes","No") -> Yes | AA5: =IF((J5+K5)>T5,"Yes","No") -> No | AB5: =IF((L5)>T5,"Yes","No") -> Yes | AE5: =IF((J5+K5)>U5,"Yes","No") -> No | AF5: =IF((L5)>U5,"Yes","No") -> Yes | AI5: Rural | AK5: Rural | AM5: Rural
A6: 4-004 | B6: Corner Brook/Stephenville | C6: 77974 | D6: =SUM(J6:M6) -> 74334.09 | E6: 7 | F6: 0.1 | G6: 0.2 | H6: 0.3 | L6: 74334.09 | O6: =J6+K6+L6+M6-C6 -> -3639.91 | P6: =((M6+L6+K6+J6)-C6)/C6 -> -0.046681073 | R6: =SUM(J6:M6) -> 74334.09 | S6: =$D6*(F6) -> 7433.409 | T6: =$D6*(G6) -> 14866.818 | U6: =$D6*(H6) -> 22300.227 | W6: =IF((J6+K6)>S6,"Yes","No") -> No | X6: =IF((L6)>S6,"Yes","No") -> Yes | AA6: =IF((J6+K6)>T6,"Yes","No") -> No | AB6: =IF((L6)>T6,"Yes","No") -> Yes | AE6: =IF((J6+K6)>U6,"Yes","No") -> No | AF6: =IF((L6)>U6,"Yes","No") -> Yes | AI6: Rural | AK6: Rural | AM6: Rural
A7: 4-005 | B7: Labrador | C7: 27656 | D7: =SUM(J7:M7) -> 26864.59 | E7: 7 | F7: 0.1 | G7: 0.2 | H7: 0.3 | M7: 26864.59 | O7: =J7+K7+L7+M7-C7 -> -791.41 | P7: =((M7+L7+K7+J7)-C7)/C7 -> -0.028616213 | R7: =SUM(J7:M7) -> 26864.59 | S7: =$D7*(F7) -> 2686.459 | T7: =$D7*(G7) -> 5372.918 | U7: =$D7*(H7) -> 8059.377 | W7: =IF((J7+K7)>S7,"Yes","No") -> No | X7: =IF((L7)>S7,"Yes","No") -> No | Y7: Yes | AA7: =IF((J7+K7)>T7,"Yes","No") -> No | AB7: =IF((L7)>T7,"Yes","No") -> No | AC7: =IF((M7)>U7,"Yes","No") -> Yes | AE7: =IF((J7+K7)>U7,"Yes","No") -> No | AF7: =IF((L7)>U7,"Yes","No") -> No | AG7: =IF((M7)>U7,"Yes","No") -> Yes | AI7: Remote | AK7: Remote | AM7: Remote
A8: 4-006 | B8: Charlottetown | C8: 95350 | D8: =SUM(J8:M8) -> 104131.96 | E8: 7 | F8: 0.25 | G8: 0.4 | H8: 0.6 | K8: 64089.92 | L8: 40042.04 | O8: =J8+K8+L8+M8-C8 -> 8781.96 | P8: =((M8+L8+K8+J8)-C8)/C8 -> 0.09210236 | R8: =SUM(J8:M8) -> 104131.96 | S8: =$D8*(F8) -> 26032.99 | T8: =$D8*(G8) -> 41652.784 | U8: =$D8*(H8) -> 62479.176 | W8: =IF((J8+K8)>S8,"Yes","No") -> Yes | AA8: =IF((J8+K8)>T8,"Yes","No") -> Yes | AE8: =IF((J8+K8)>U8,"Yes","No") -> Yes | AI8: Metro/Urban | AK8: Metro/Urban | AM8: Metro/Urban
A9: 4-007 | B9: Summerside | C9: 47557 | D9: =SUM(J9:M9) -> 50199.03 | E9: 7 | F9: 0.15 | G9: 0.3 | H9: 0.4 | L9: 50199.03 | O9: =J9+K9+L9+M9-C9 -> 2642.03 | P9: =((M9+L9+K9+J9)-C9)/C9 -> 0.055555018 | R9: =SUM(J9:M9) -> 50199.03 | S9: =$D9*(F9) -> 7529.8545 | T9: =$D9*(G9) -> 15059.709 | U9: =$D9*(H9) -> 20079.612 | W9: =IF((J9+K9)>S9,"Yes","No") -> No | X9: =IF((L9)>S9,"Yes","No") -> Yes | AA9: =IF((J9+K9)>T9,"Yes","No") -> No | AB9: =IF((L9)>T9,"Yes","No") -> Yes | AE9: =IF((J9+K9)>U9,"Yes","No") -> No | AF9: =IF((L9)>U9,"Yes","No") -> Yes | AI9: Rural | AK9: Rural | AM9: Rural
A10: 4-008 | B10: Yarmouth | C10: 55609 | D10: =SUM(J10:M10) -> 55558.51 | E10: 7 | F10: 0.2 | G10: 0.35 | H10: 0.5 | L10: 55558.51 | O10: =J10+K10+L10+M10-C10 -> -50.49 | P10: =((M10+L10+K10+J10)-C10)/C10 -> -0.00090794656 | R10: =SUM(J10:M10) -> 55558.51 | S10: =$D10*(F10) -> 11111.702 | T10: =$D10*(G10) -> 19445.479 | U10: =$D10*(H10) -> 27779.255 | W10: =IF((J10+K10)>S10,"Yes","No") -> No | X10: =IF((L10)>S10,"Yes","No") -> Yes | AA10: =IF((J10+K10)>T10,"Yes","No") -> No | AB10: =IF((L10)>T10,"Yes","No") -> Yes | AE10: =IF((J10+K10)>U10,"Yes","No") -> No | AF10: =IF((L10)>U10,"Yes","No") -> Yes | AI10: Rural | AK10: Rural | AM10: Rural
A11: 4-009 | B11: Bridgewater/Kentville | C11: 139289 | D11: =SUM(J11:M11) -> 143860.3 | E11: 7 | F11: 0.2 | G11: 0.35 | H11: 0.5 | L11: 143860.3 | O11: =J11+K11+L11+M11-C11 -> 4571.3 | P11: =((M11+L11+K11+J11)-C11)/C11 -> 0.032818816 | R11: =SUM(J11:M11) -> 143860.3 | S11: =$D11*(F11) -> 28772.06 | T11: =$D11*(G11) -> 50351.105 | U11: =$D11*(H11) -> 71930.15 | W11: =IF((J11+K11)>S11,"Yes","No") -> No | X11: =IF((L11)>S11,"Yes","No") -> Yes | AA11: =IF((J11+K11)>T11,"Yes","No") -> No | AB11: =IF((L11)>T11,"Yes","No") -> Yes | AE11: =IF((J11+K11)>U11,"Yes","No") -> No | AF11: =IF((L11)>U11,"Yes","No") -> Yes | AI11: Rural | AK11: Rural | AM11: Rural
A12: 4-010 | B12: Halifax | C12: 435820 | D12: =SUM(J12:M12) -> 474931.84 | E12: 5 | F12: 0.3 | G12: 0.5 | H12: 0.7 | K12: 389899.74 | L12: 85032.1 | O12: =J12+K12+L12+M12-C12 -> 39111.84 | P12: =((M12+L12+K12+J12)-C12)/C12 -> 0.089743105 | R12: =SUM(J12:M12) -> 474931.84 | S12: =$D12*(F12) -> 142479.55 | T12: =$D12*(G12) -> 237465.92 | U12: =$D12*(H12) -> 332452.29 | W12: =IF((J12+K12)>S12,"Yes","No") -> Yes | AA12: =IF((J12+K12)>T12,"Yes","No") -> Yes | AE12: =IF((J12+K12)>U12,"Yes","No") -> Yes | AI12: Metro/Urban | AK12: Metro/Urban | AM12: Metro/Urban
A13: 4-011 | B13: Truro | C13: 56649 | D13: =SUM(J13:M13) -> 57465.43 | E13: 7 | F13: 0.15 | G13: 0.3 | H13: 0.4 | L13: 57465.43 | O13: =J13+K13+L13+M13-C13 -> 816.43 | P13: =((M13+L13+K13+J13)-C13)/C13 -> 0.014412081 | R13: =SUM(J13:M13) -> 57465.43 | S13: =$D13*(F13) -> 8619.8145 | T13: =$D13*(G13) -> 17239.629 | U13: =$D13*(H13) -> 22986.172 | W13: =IF((J13+K13)>S13,"Yes","No") -> No | X13: =IF((L13)>S13,"Yes","No") -> Yes | AA13: =IF((J13+K13)>T13,"Yes","No") -> No | AB13: =IF((L13)>T13,"Yes","No") -> Yes | AE13: =IF((J13+K13)>U13,"Yes","No") -> No | AF13: =IF((L13)>U13,"Yes","No") -> Yes | AI13: Rural | AK13: Rural | AM13: Rural
A14: 4-012 | B14: Amherst | C14: 33373 | D14: =SUM(J14:M14) -> 34197.59 | E14: 7 | F14: 0.1 | G14: 0.2 | H14: 0.3 | L14: 34197.59 | O14: =J14+K14+L14+M14-C14 -> 824.59 | P14: =((M14+L14+K14+J14)-C14)/C14 -> 0.024708297 | R14: =SUM(J14:M14) -> 34197.59 | S14: =$D14*(F14) -> 3419.759 | T14: =$D14*(G14) -> 6839.518 | U14: =$D14*(H14) -> 10259.277 | W14: =IF((J14+K14)>S14,"Yes","No") -> No | X14: =IF((L14)>S14,"Yes","No") -> Yes | AA14: =IF((J14+K14)>T14,"Yes","No") -> No | AB14: =IF((L14)>T14,"Yes","No") -> Yes | AE14: =IF((J14+K14)>U14,"Yes","No") -> No | AF14: =IF((L14)>U14,"Yes","No") -> Yes | AI14: Rural | AK14: Rural | AM14: Rural
A15: 4-013 | B15: Antigonish/New Glasgow | C15: 71445 | D15: =SUM(J15:M15) -> 71983.16 | E15: 7 | F15: 0.15 | G15: 0.3 | H15: 0.4 | L15: 71983.16 | O15: =J15+K15+L15+M15-C15 -> 538.16 | P15: =((M15+L15+K15+J15)-C15)/C15 -> 0.0075325075 | R15: =SUM(J15:M15) -> 71983.16 | S15: =$D15*(F15) -> 10797.474 | T15: =$D15*(G15) -> 21594.948 | U15: =$D15*(H15) -> 28793.264 | W15: =IF((J15+K15)>S15,"Yes","No") -> No | X15: =IF((L15)>S15,"Yes","No") -> Yes | AA15: =IF((J15+K15)>T15,"Yes","No") -> No | AB15: =IF((L15)>T15,"Yes","No") -> Yes | AE15: =IF((J15+K15)>U15,"Yes","No") -> No | AF15: =IF((L15)>U15,"Yes","No") -> Yes | AI15: Rural | AK15: Rural | AM15: Rural
A16: 4-014 | B16: Sydney | C16: 131379 | D16: =SUM(J16:M16) -> 131343.37 | E16: 7 | F16: 0.3 | G16: 0.5 | H16: 0.7 | L16: 131343.37 | O16: =J16+K16+L16+M16-C16 -> -35.63 | P16: =((M16+L16+K16+J16)-C16)/C16 -> -0.00027120012 | R16: =SUM(J16:M16) -> 131343.37 | S16: =$D16*(F16) -> 39403.011 | T16: =$D16*(G16) -> 65671.685 | U16: =$D16*(H16) -> 91940.359 | W16: =IF((J16+K16)>S16,"Yes","No") -> No | X16: =IF((L16)>S16,"Yes","No") -> Yes | AA16: =IF((J16+K16)>T16,"Yes","No") -> No | AB16: =IF((L16)>T16,"Yes","No") -> Yes | AE16: =IF((J16+K16)>U16,"Yes","No") -> No | AF16: =IF((L16)>U16,"Yes","No") -> Yes | AI16: Rural | AK16: Rural | AM16: Rural
A17: 4-015 | B17: Saint John | C17: 142898 | D17: =SUM(J17:M17) -> 147694.56 | E17: 7 | F17: 0.3 | G17: 0.5 | H17: 0.7 | K17: 103766.22 | L17: 43928.34 | O17: =J17+K17+L17+M17-C17 -> 4796.56 | P17: =((M17+L17+K17+J17)-C17)/C17 -> 0.03356632 | R17: =SUM(J17:M17) -> 147694.56 | S17: =$D17*(F17) -> 44308.368 | T17: =$D17*(G17) -> 73847.28 | U17: =$D17*(H17) -> 103386.19 | W17: =IF((J17+K17)>S17,"Yes","No") -> Yes | AA17: =IF((J17+K17)>T17,"Yes","No") -> Yes | AE17: =IF((J17+K17)>U17,"Yes","No") -> Yes | AI17: Metro/Urban | AK17: Metro/Urban | AM17: Metro/Urban
A18: 4-016 | B18: St. Stephen | C18: 25087 | D18: =SUM(J18:M18) -> 25641.85 | E18: 7 | F18: 0.05 | G18: 0.15 | H18: 0.25 | L18: 25641.85 | O18: =J18+K18+L18+M18-C18 -> 554.85 | P18: =((M18+L18+K18+J18)-C18)/C18 -> 0.022117033 | R18: =SUM(J18:M18) -> 25641.85 | S18: =$D18*(F18) -> 1282.0925 | T18: =$D18*(G18) -> 3846.2775 | U18: =$D18*(H18) -> 6410.4625 | W18: =IF((J18+K18)>S18,"Yes","No") -> No | X18: =IF((L18)>S18,"Yes","No") -> Yes | AA18: =IF((J18+K18)>T18,"Yes","No") -> No | AB18: =IF((L18)>T18,"Yes","No") -> Yes | AE18: =IF((J18+K18)>U18,"Yes","No") -> No | AF18: =IF((L18)>U18,"Yes","No") -> Yes | AI18: Rural | AK18: Rural | AM18: Rural
A19: 4-017 | B19: Fredericton | C19: 164871 | D19: =SUM(J19:M19) -> 171650.38 | E19: 7 | F19: 0.25 | G19: 0.4 | H19: 0.6 | K19: 94661.36 | L19: 76989.02 | O19: =J19+K19+L19+M19-C19 -> 6779.38 | P19: =((M19+L19+K19+J19)-C19)/C19 -> 0.041119299 | R19: =SUM(J19:M19) -> 171650.38 | S19: =$D19*(F19) -> 42912.595 | T19: =$D19*(G19) -> 68660.152 | U19: =$D19*(H19) -> 102990.23 | W19: =IF((J19+K19)>S19,"Yes","No") -> Yes | AA19: =IF((J19+K19)>T19,"Yes","No") -> Yes | AE19: =IF((J19+K19)>U19,"Yes","No") -> No | AF19: =IF((L19)>U19,"Yes","No") -> No | AG19: =IF((M19)>U19,"Yes","No") -> No | AI19: Metro/Urban | AK19: Metro/Urban | AM19: Mix | AO19: Yes | AR19: =U19-K19 -> 8328.868 | AS19: =AR19/L19*100 -> 10.818254
A20: 4-018 | B20: Moncton | C20: 178500 | D20: =SUM(J20:M20) -> 194002.2 | E20: 5 | F20: 0.25 | G20: 0.4 | H20: 0.6 | K20: 137631.83 | L20: 56370.37 | O20: =J20+K20+L20+M20-C20 -> 15502.2 | P20: =((M20+L20+K20+J20)-C20)/C20 -> 0.086847059 | R20: =SUM(J20:M20) -> 194002.2 | S20: =$D20*(F20) -> 48500.55 | T20: =$D20*(G20) -> 77600.88 | U20: =$D20*(H20) -> 116401.32 | W20: =IF((J20+K20)>S20,"Yes","No") -> Yes | AA20: =IF((J20+K20)>T20,"Yes","No") -> Yes | AE20: =IF((J20+K20)>U20,"Yes","No") -> Yes | AI20: Metro/Urban | AK20: Metro/Urban | AM20: Metro/Urban
A21: 4-019 | B21: Miramichi/Bathurst | C21: 156025 | D21: =SUM(J21:M21) -> 157384.33 | E21: 7 | F21: 0.15 | G21: 0.3 | H21: 0.4 | L21: 157384.33 | O21: =J21+K21+L21+M21-C21 -> 1359.33 | P21: =((M21+L21+K21+J21)-C21)/C21 -> 0.0087122577 | R21: =SUM(J21:M21) -> 157384.33 | S21: =$D21*(F21) -> 23607.65 | T21: =$D21*(G21) -> 47215.299 | U21: =$D21*(H21) -> 62953.732 | W21: =IF((J21+K21)>S21,"Yes","No") -> No | X21: =IF((L21)>S21,"Yes","No") -> Yes | AA21: =IF((J21+K21)>T21,"Yes","No") -> No | AB21: =IF((L21)>T21,"Yes","No") -> Yes | AE21: =IF((J21+K21)>U21,"Yes","No") -> No | AF21: =IF((L21)>U21,"Yes","No") -> Yes | AI21: Rural | AK21: Rural | AM21: Rural
A22: 4-020 | B22: Grand Falls | C22: 24936 | D22: =SUM(J22:M22) -> 24315.39 | E22: 7 | F22: 0.1 | G22: 0.2 | H22: 0.3 | L22: 24315.39 | O22: =J22+K22+L22+M22-C22 -> -620.61 | P22: =((M22+L22+K22+J22)-C22)/C22 -> -0.024888114 | R22: =SUM(J22:M22) -> 24315.39 | S22: =$D22*(F22) -> 2431.539 | T22: =$D22*(G22) -> 4863.078 | U22: =$D22*(H22) -> 7294.617 | W22: =IF((J22+K22)>S22,"Yes","No") -> No | X22: =IF((L22)>S22,"Yes","No") -> Yes | AA22: =IF((J22+K22)>T22,"Yes","No") -> No | AB22: =IF((L22)>T22,"Yes","No") -> Yes | AE22: =IF((J22+K22)>U22,"Yes","No") -> No | AF22: =IF((L22)>U22,"Yes","No") -> Yes | AI22: Rural | AK22: Rural | AM22: Rural
A23: 4-021 | B23: Edmundston | C23: 26504 | D23: =SUM(J23:M23) -> 26685.66 | E23: 7 | F23: 0.25 | G23: 0.4 | H23: 0.6 | L23: 26685.66 | O23: =J23+K23+L23+M23-C23 -> 181.66 | P23: =((M23+L23+K23+J23)-C23)/C23 -> 0.0068540598 | R23: =SUM(J23:M23) -> 26685.66 | S23: =$D23*(F23) -> 6671.415 | T23: =$D23*(G23) -> 10674.264 | U23: =$D23*(H23) -> 16011.396 | W23: =IF((J23+K23)>S23,"Yes","No") -> No | X23: =IF((L23)>S23,"Yes","No") -> Yes | AA23: =IF((J23+K23)>T23,"Yes","No") -> No | AB23: =IF((L23)>T23,"Yes","No") -> Yes | AE23: =IF((J23+K23)>U23,"Yes","No") -> No | AF23: =IF((L23)>U23,"Yes","No") -> Yes | AI23: Rural | AK23: Rural | AM23: Rural
A24: 4-022 | B24: Campbellton | C24: 26776 | D24: =SUM(J24:M24) -> 26052.67 | E24: 7 | F24: 0.1 | G24: 0.2 | H24: 0.3 | L24: 26052.67 | O24: =J24+K24+L24+M24-C24 -> -723.33 | P24: =((M24+L24+K24+J24)-C24)/C24 -> -0.027014117 | R24: =SUM(J24:M24) -> 26052.67 | S24: =$D24*(F24) -> 2605.267 | T24: =$D24*(G24) -> 5210.534 | U24: =$D24*(H24) -> 7815.801 | W24: =IF((J24+K24)>S24,"Yes","No") -> No | X24: =IF((L24)>S24,"Yes","No") -> Yes | AA24: =IF((J24+K24)>T24,"Yes","No") -> No | AB24: =IF((L24)>T24,"Yes","No") -> Yes | AE24: =IF((J24+K24)>U24,"Yes","No") -> No | AF24: =IF((L24)>U24,"Yes","No") -> Yes | AI24: Rural | AK24: Rural | AM24: Rural
A25: 4-023 | B25: Matane | C25: 112039 | D25: =SUM(J25:M25) -> 111242.45 | E25: 7 | F25: 0.15 | G25: 0.3 | H25: 0.4 | L25: 111242.45 | O25: =J25+K25+L25+M25-C25 -> -796.55 | P25: =((M25+L25+K25+J25)-C25)/C25 -> -0.0071095779 | R25: =SUM(J25:M25) -> 111242.45 | S25: =$D25*(F25) -> 16686.368 | T25: =$D25*(G25) -> 33372.735 | U25: =$D25*(H25) -> 44496.98 | W25: =IF((J25+K25)>S25,"Yes","No") -> No | X25: =IF((L25)>S25,"Yes","No") -> Yes | AA25: =IF((J25+K25)>T25,"Yes","No") -> No | AB25: =IF((L25)>T25,"Yes","No") -> Yes | AE25: =IF((J25+K25)>U25,"Yes","No") -> No | AF25: =IF((L25)>U25,"Yes","No") -> Yes | AI25: Rural | AK25: Rural | AM25: Rural
A26: 4-024 | B26: Mont-Joli | C26: 37788 | D26: =SUM(J26:M26) -> 37612.68 | E26: 7 | F26: 0.05 | G26: 0.15 | H26: 0.25 | L26: 37612.68 | O26: =J26+K26+L26+M26-C26 -> -175.32 | P26: =((M26+L26+K26+J26)-C26)/C26 -> -0.0046395681 | R26: =SUM(J26:M26) -> 37612.68 | S26: =$D26*(F26) -> 1880.634 | T26: =$D26*(G26) -> 5641.902 | U26: =$D26*(H26) -> 9403.17 | W26: =IF((J26+K26)>S26,"Yes","No") -> No | X26: =IF((L26)>S26,"Yes","No") -> Yes | AA26: =IF((J26+K26)>T26,"Yes","No") -> No | AB26: =IF((L26)>T26,"Yes","No") -> Yes | AE26: =IF((J26+K26)>U26,"Yes","No") -> No | AF26: =IF((L26)>U26,"Yes","No") -> Yes | AI26: Rural | AK26: Rural | AM26: Rural
A27: 4-025 | B27: Rimouski | C27: 56619 | D27: =SUM(J27:M27) -> 57190.86 | E27: 7 | F27: 0.25 | G27: 0.4 | H27: 0.6 | K27: 46032.23 | L27: 11158.63 | O27: =J27+K27+L27+M27-C27 -> 571.86 | P27: =((M27+L27+K27+J27)-C27)/C27 -> 0.010100143 | R27: =SUM(J27:M27) -> 57190.86 | S27: =$D27*(F27) -> 14297.715 | T27: =$D27*(G27) -> 22876.344 | U27: =$D27*(H27) -> 34314.516 | W27: =IF((J27+K27)>S27,"Yes","No") -> Yes | AA27: =IF((J27+K27)>T27,"Yes","No") -> Yes | AE27: =IF((J27+K27)>U27,"Yes","No") -> Yes | AI27: Metro/Urban | AK27: Metro/Urban | AM27: Metro/Urban
A28: 4-026 | B28: Rivière-du-Loup | C28: 82869 | D28: =SUM(J28:M28) -> 84581.63 | E28: 7 | F28: 0.2 | G28: 0.35 | H28: 0.5 | L28: 84581.63 | O28: =J28+K28+L28+M28-C28 -> 1712.63 | P28: =((M28+L28+K28+J28)-C28)/C28 -> 0.020666715 | R28: =SUM(J28:M28) -> 84581.63 | S28: =$D28*(F28) -> 16916.326 | T28: =$D28*(G28) -> 29603.57 | U28: =$D28*(H28) -> 42290.815 | W28: =IF((J28+K28)>S28,"Yes","No") -> No | X28: =IF((L28)>S28,"Yes","No") -> Yes | AA28: =IF((J28+K28)>T28,"Yes","No") -> No | AB28: =IF((L28)>T28,"Yes","No") -> Yes | AE28: =IF((J28+K28)>U28,"Yes","No") -> No | AF28: =IF((L28)>U28,"Yes","No") -> Yes | AI28: Rural | AK28: Rural | AM28: Rural
A29: 4-027 | B29: La Malbaie | C29: 28193 | D29: =SUM(J29:M29) -> 28507.84 | E29: 7 | F29: 0.15 | G29: 0.3 | H29: 0.4 | L29: 28507.84 | O29: =J29+K29+L29+M29-C29 -> 314.84 | P29: =((M29+L29+K29+J29)-C29)/C29 -> 0.011167311 | R29: =SUM(J29:M29) -> 28507.84 | S29: =$D29*(F29) -> 4276.176 | T29: =$D29*(G29) -> 8552.352 | U29: =$D29*(H29) -> 11403.136 | W29: =IF((J29+K29)>S29,"Yes","No") -> No | X29: =IF((L29)>S29,"Yes","No") -> Yes | AA29: =IF((J29+K29)>T29,"Yes","No") -> No | AB29: =IF((L29)>T29,"Yes","No") -> Yes | AE29: =IF((J29+K29)>U29,"Yes","No") -> No | AF29: =IF((L29)>U29,"Yes","No") -> Yes | AI29: Rural | AK29: Rural | AM29: Rural
A30: 4-028 | B30: Chicoutimi-Jonquière | C30: 218377 | D30: =SUM(J30:M30) -> 218307.6 | E30: 5 | F30: 0.3 | G30: 0.5 | H30: 0.7 | K30: 126748.37 | L30: 91559.23 | O30: =J30+K30+L30+M30-C30 -> -69.4 | P30: =((M30+L30+K30+J30)-C30)/C30 -> -0.00031779904 | R30: =SUM(J30:M30) -> 218307.6 | S30: =$D30*(F30) -> 65492.28 | T30: =$D30*(G30) -> 109153.8 | U30: =$D30*(H30) -> 152815.32 | W30: =IF((J30+K30)>S30,"Yes","No") -> Yes | AA30: =IF((J30+K30)>T30,"Yes","No") -> Yes | AE30: =IF((J30+K30)>U30,"Yes","No") -> No | AF30: =IF((L30)>U30,"Yes","No") -> No | AG30: =IF((M30)>U30,"Yes","No") -> No | AI30: Metro/Urban | AK30: Metro/Urban | AM30: Mix | AO30: Yes | AR30: =U30-K30 -> 26066.95 | AS30: =AR30/L30*100 -> 28.470041
A31: 4-029 | B31: Montmagny | C31: 56808 | D31: =SUM(J31:M31) -> 56207.2 | E31: 7 | F31: 0.2 | G31: 0.35 | H31: 0.5 | L31: 56207.2 | O31: =J31+K31+L31+M31-C31 -> -600.8 | P31: =((M31+L31+K31+J31)-C31)/C31 -> -0.010575975 | R31: =SUM(J31:M31) -> 56207.2 | S31: =$D31*(F31) -> 11241.44 | T31: =$D31*(G31) -> 19672.52 | U31: =$D31*(H31) -> 28103.6 | W31: =IF((J31+K31)>S31,"Yes","No") -> No | X31: =IF((L31)>S31,"Yes","No") -> Yes | AA31: =IF((J31+K31)>T31,"Yes","No") -> No | AB31: =IF((L31)>T31,"Yes","No") -> Yes | AE31: =IF((J31+K31)>U31,"Yes","No") -> No | AF31: =IF((L31)>U31,"Yes","No") -> Yes | AI31: Rural | AK31: Rural | AM31: Rural
A32: 4-030 | B32: Québec | C32: 904330 | D32: =SUM(J32:M32) -> 942192.61 | E32: 5 | F32: 0.3 | G32: 0.5 | H32: 0.7 | K32: 795726.85 | L32: 146465.76 | O32: =J32+K32+L32+M32-C32 -> 37862.61 | P32: =((M32+L32+K32+J32)-C32)/C32 -> 0.041868134 | R32: =SUM(J32:M32) -> 942192.61 | S32: =$D32*(F32) -> 282657.78 | T32: =$D32*(G32) -> 471096.3 | U32: =$D32*(H32) -> 659534.83 | W32: =IF((J32+K32)>S32,"Yes","No") -> Yes | AA32: =IF((J32+K32)>T32,"Yes","No") -> Yes | AE32: =IF((J32+K32)>U32,"Yes","No") -> Yes | AI32: Metro/Urban | AK32: Metro/Urban | AM32: Metro/Urban
A33: 4-031 | B33: Sainte-Marie | C33: 53258 | D33: =SUM(J33:M33) -> 54962.76 | E33: 7 | F33: 0.25 | G33: 0.4 | H33: 0.6 | L33: 54962.76 | O33: =J33+K33+L33+M33-C33 -> 1704.76 | P33: =((M33+L33+K33+J33)-C33)/C33 -> 0.032009463 | R33: =SUM(J33:M33) -> 54962.76 | S33: =$D33*(F33) -> 13740.69 | T33: =$D33*(G33) -> 21985.104 | U33: =$D33*(H33) -> 32977.656 | W33: =IF((J33+K33)>S33,"Yes","No") -> No | X33: =IF((L33)>S33,"Yes","No") -> Yes | AA33: =IF((J33+K33)>T33,"Yes","No") -> No | AB33: =IF((L33)>T33,"Yes","No") -> Yes | AE33: =IF((J33+K33)>U33,"Yes","No") -> No | AF33: =IF((L33)>U33,"Yes","No") -> Yes | AI33: Rural | AK33: Rural | AM33: Rural
A34: 4-032 | B34: Saint-Georges | C34: 71425 | D34: =SUM(J34:M34) -> 72535.13 | E34: 7 | F34: 0.2 | G34: 0.35 | H34: 0.5 | L34: 72535.13 | O34: =J34+K34+L34+M34-C34 -> 1110.13 | P34: =((M34+L34+K34+J34)-C34)/C34 -> 0.015542597 | R34: =SUM(J34:M34) -> 72535.13 | S34: =$D34*(F34) -> 14507.026 | T34: =$D34*(G34) -> 25387.296 | U34: =$D34*(H34) -> 36267.565 | W34: =IF((J34+K34)>S34,"Yes","No") -> No | X34: =IF((L34)>S34,"Yes","No") -> Yes | AA34: =IF((J34+K34)>T34,"Yes","No") -> No | AB34: =IF((L34)>T34,"Yes","No") -> Yes | AE34: =IF((J34+K34)>U34,"Yes","No") -> No | AF34: =IF((L34)>U34,"Yes","No") -> Yes | AI34: Rural | AK34: Rural | AM34: Rural
A35: 4-033 | B35: Lac-Mégantic | C35: 24223 | D35: =SUM(J35:M35) -> 24584.22 | E35: 7 | F35: 0.2 | G35: 0.35 | H35: 0.5 | L35: 24584.22 | O35: =J35+K35+L35+M35-C35 -> 361.22 | P35: =((M35+L35+K35+J35)-C35)/C35 -> 0.014912273 | R35: =SUM(J35:M35) -> 24584.22 | S35: =$D35*(F35) -> 4916.844 | T35: =$D35*(G35) -> 8604.477 | U35: =$D35*(H35) -> 12292.11 | W35: =IF((J35+K35)>S35,"Yes","No") -> No | X35: =IF((L35)>S35,"Yes","No") -> Yes | AA35: =IF((J35+K35)>T35,"Yes","No") -> No | AB35: =IF((L35)>T35,"Yes","No") -> Yes | AE35: =IF((J35+K35)>U35,"Yes","No") -> No | AF35: =IF((L35)>U35,"Yes","No") -> Yes | AI35: Rural | AK35: Rural | AM35: Rural
A36: 4-034 | B36: Thetford Mines | C36: 42019 | D36: =SUM(J36:M36) -> 43000.79 | E36: 7 | F36: 0.3 | G36: 0.5 | H36: 0.7 | L36: 43000.79 | O36: =J36+K36+L36+M36-C36 -> 981.79 | P36: =((M36+L36+K36+J36)-C36)/C36 -> 0.023365382 | R36: =SUM(J36:M36) -> 43000.79 | S36: =$D36*(F36) -> 12900.237 | T36: =$D36*(G36) -> 21500.395 | U36: =$D36*(H36) -> 30100.553 | W36: =IF((J36+K36)>S36,"Yes","No") -> No | X36: =IF((L36)>S36,"Yes","No") -> Yes | AA36: =IF((J36+K36)>T36,"Yes","No") -> No | AB36: =IF((L36)>T36,"Yes","No") -> Yes | AE36: =IF((J36+K36)>U36,"Yes","No") -> No | AF36: =IF((L36)>U36,"Yes","No") -> Yes | AI36: Rural | AK36: Rural | AM36: Rural
A37: 4-035 | B37: Plessisville | C37: 22772 | D37: =SUM(J37:M37) -> 23054.36 | E37: 7 | F37: 0.1 | G37: 0.2 | H37: 0.3 | K37: 10086.48 | L37: 12967.88 | O37: =J37+K37+L37+M37-C37 -> 282.36 | P37: =((M37+L37+K37+J37)-C37)/C37 -> 0.012399438 | R37: =SUM(J37:M37) -> 23054.36 | S37: =$D37*(F37) -> 2305.436 | T37: =$D37*(G37) -> 4610.872 | U37: =$D37*(H37) -> 6916.308 | W37: =IF((J37+K37)>S37,"Yes","No") -> Yes | AA37: =IF((J37+K37)>T37,"Yes","No") -> Yes | AE37: =IF((J37+K37)>U37,"Yes","No") -> Yes | AI37: Metro/Urban | AK37: Metro/Urban | AM37: Metro/Urban
A38: 4-036 | B38: La Tuque | C38: 16219 | D38: =SUM(J38:M38) -> 16376.01 | E38: 7 | F38: 0.2 | G38: 0.35 | H38: 0.5 | L38: 16376.01 | O38: =J38+K38+L38+M38-C38 -> 157.01 | P38: =((M38+L38+K38+J38)-C38)/C38 -> 0.0096806215 | R38: =SUM(J38:M38) -> 16376.01 | S38: =$D38*(F38) -> 3275.202 | T38: =$D38*(G38) -> 5731.6035 | U38: =$D38*(H38) -> 8188.005 | W38: =IF((J38+K38)>S38,"Yes","No") -> No | X38: =IF((L38)>S38,"Yes","No") -> Yes | AA38: =IF((J38+K38)>T38,"Yes","No") -> No | AB38: =IF((L38)>T38,"Yes","No") -> Yes | AE38: =IF((J38+K38)>U38,"Yes","No") -> No | AF38: =IF((L38)>U38,"Yes","No") -> Yes | AI38: Rural | AK38: Rural | AM38: Rural
A39: 4-037 | B39: Trois-Rivières | C39: 265152 | D39: =SUM(J39:M39) -> 272644.1 | E39: 5 | F39: 0.3 | G39: 0.5 | H39: 0.7 | K39: 216627.1 | L39: 56017 | O39: =J39+K39+L39+M39-C39 -> 7492.1 | P39: =((M39+L39+K39+J39)-C39)/C39 -> 0.028255868 | R39: =SUM(J39:M39) -> 272644.1 | S39: =$D39*(F39) -> 81793.23 | T39: =$D39*(G39) -> 136322.05 | U39: =$D39*(H39) -> 190850.87 | W39: =IF((J39+K39)>S39,"Yes","No") -> Yes | AA39: =IF((J39+K39)>T39,"Yes","No") -> Yes | AE39: =IF((J39+K39)>U39,"Yes","No") -> Yes | AI39: Metro/Urban | AK39: Metro/Urban | AM39: Metro/Urban
A40: 4-038 | B40: Louiseville | C40: 21708 | D40: =SUM(J40:M40) -> 22170.19 | E40: 7 | F40: 0.15 | G40: 0.3 | H40: 0.4 | L40: 22170.19 | O40: =J40+K40+L40+M40-C40 -> 462.19 | P40: =((M40+L40+K40+J40)-C40)/C40 -> 0.021291229 | R40: =SUM(J40:M40) -> 22170.19 | S40: =$D40*(F40) -> 3325.5285 | T40: =$D40*(G40) -> 6651.057 | U40: =$D40*(H40) -> 8868.076 | W40: =IF((J40+K40)>S40,"Yes","No") -> No | X40: =IF((L40)>S40,"Yes","No") -> Yes | AA40: =IF((J40+K40)>T40,"Yes","No") -> No | AB40: =IF((L40)>T40,"Yes","No") -> Yes | AE40: =IF((J40+K40)>U40,"Yes","No") -> No | AF40: =IF((L40)>U40,"Yes","No") -> Yes | AI40: Rural | AK40: Rural | AM40: Rural
...
